Workbook

Sheet CONFIGURACIÓN
A1: SISTEMA INTEGRAL DE CONTROLLER FINANCIERO
A2: CONFIGURACIÓN DEL ANÁLISIS
A5: Parámetro | B5: EMPRESA EJEMPLO S.A.S. | C5: Descripción
A6: Nombre de la Empresa: | C6: Ingrese el nombre completo de la empresa
A7: Sector Económico: | B7: Manufactura | C7: Seleccione el sector de la lista
A8: Código CIIU: | B8: 1234 | C8: Código de clasificación industrial
A9: Moneda: | B9: COP | C9: Moneda de presentación
A10: Unidad de Medida: | B10: Millones | C10: Miles, Millones o Unidades
A11: Año Base de Análisis: | B11: 2024 | C11: Año actual de análisis
A12: Años Históricos: | B12: 3 | C12: Número de años históricos (2-5)
A13: Años de Proyección: | B13: 5 | C13: Años para proyectar (5-7)
A15: Tasa de Impuesto de Renta: | B15: 35% | C15: Colombia: 35% para empresas
A16: Tasa Libre de Riesgo: | B16: 12.5% | C16: TES Colombia 10 años aprox.

Sheet INSTRUCCIONES
A1: GUÍA DE USO - SISTEMA INTEGRAL DE CONTROLLER FINANCIERO
A3: BIENVENIDO AL SISTEMA INTEGRAL DE CONTROLLER FINANCIERO
A5: Esta herramienta ha sido diseñada para realizar análisis financiero completo de empresas,
A6: siguiendo la metodología de consultoría financiera para PYMEs colombianas.
A8: ═══════════════════════════════════════════════════════════════════════════════
A10: PASO 1: CONFIGURACIÓN INICIAL
A11: • Vaya a la hoja 'CONFIGURACIÓN'
A12: • Complete los datos básicos de la empresa (nombre, sector, CIIU, etc.)
A13: • Las celdas de entrada están marcadas en AZUL con fondo gris
A14: • Seleccione el sector económico de la lista desplegable
A16: PASO 2: INGRESAR ESTADO DE RESULTADOS
A17: • Vaya a la hoja 'EERR' (Estado de Resultados)
... A116: ═══════════════════════════════════════════════════════════════════════════════

Sheet EERR
A1: ESTADO DE RESULTADOS
A2: Cifras en: [Referencia a Configuración]
A4: CONCEPTO | B4: Año 2022 | C4: AV% | D4: Año 2023 | E4: AV% | F4: AH% | G4: Año 2024 | H4: AV% | I4: AH% | J4: Promedio | K4: Tendencia
A5: Ingresos de Actividades Ordinarias (Ventas) | B5: 15000 | C5: =IFERROR(B5/B$5,0) | D5: 17500 | E5: =IFERROR(D5/D$5,0) | F5: =IFERROR((D5-B5)/B5,0) | G5: 20000 | H5: =IFERROR(G5/G$5,0) | I5: =IFERROR((G5-D5)/D5,0) | J5: =IFERROR(AVERAGE(B5,D5,G5),0)
A6: (-) Costo de Ventas / Costo de Servicios | B6: 9000 | C6: =IFERROR(B6/B$5,0) | D6: 10500 | E6: =IFERROR(D6/D$5,0) | F6: =IFERROR((D6-B6)/B6,0) | G6: 12000 | H6: =IFERROR(G6/G$5,0) | I6: =IFERROR((G6-D6)/D6,0) | J6: =IFERROR(AVERAGE(B6,D6,G6),0)
A7: (=) UTILIDAD BRUTA | B7: =IFERROR(B5-B6,0) | C7: =IFERROR(B7/B$5,0) | D7: =IFERROR(D5-D6,0) | E7: =IFERROR(D7/D$5,0) | F7: =IFERROR((D7-B7)/B7,0) | G7: =IFERROR(G5-G6,0) | H7: =IFERROR(G7/G$5,0) | I7: =IFERROR((G7-D7)/D7,0) | J7: =IFERROR(AVERAGE(B7,D7,G7),0)
C8: =IFERROR(B8/B$5,0) | E8: =IFERROR(D8/D$5,0) | F8: =IFERROR((D8-B8)/B8,0) | H8: =IFERROR(G8/G$5,0) | I8: =IFERROR((G8-D8)/D8,0) | J8: =IFERROR(AVERAGE(B8,D8,G8),0)
A9: (-) Gastos Administrativos (excepto Deprec. y Amort.) | B9: 2500 | C9: =IFERROR(B9/B$5,0) | D9: 2700 | E9: =IFERROR(D9/D$5,0) | F9: =IFERROR((D9-B9)/B9,0) | G9: 3000 | H9: =IFERROR(G9/G$5,0) | I9: =IFERROR((G9-D9)/D9,0) | J9: =IFERROR(AVERAGE(B9,D9,G9),0)
A10: (-) Gastos de Ventas (excepto Deprec. y Amort.) | B10: 1500 | C10: =IFERROR(B10/B$5,0) | D10: 1600 | E10: =IFERROR(D10/D$5,0) | F10: =IFERROR((D10-B10)/B10,0) | G10: 1800 | H10: =IFERROR(G10/G$5,0) | I10: =IFERROR((G10-D10)/D10,0) | J10: =IFERROR(AVERAGE(B10,D10,G10),0)
A11: (-) Depreciación | B11: 400 | C11: =IFERROR(B11/B$5,0) | D11: 450 | E11: =IFERROR(D11/D$5,0) | F11: =IFERROR((D11-B11)/B11,0) | G11: 500 | H11: =IFERROR(G11/G$5,0) | I11: =IFERROR((G11-D11)/D11,0) | J11: =IFERROR(AVERAGE(B11,D11,G11),0)
A12: (-) Amortización | B12: 100 | C12: =IFERROR(B12/B$5,0) | D12: 110 | E12: =IFERROR(D12/D$5,0) | F12: =IFERROR((D12-B12)/B12,0) | G12: 120 | H12: =IFERROR(G12/G$5,0) | I12: =IFERROR((G12-D12)/D12,0) | J12: =IFERROR(AVERAGE(B12,D12,G12),0)
A13: (=) EBITDA | B13: =IFERROR(B7-B9-B10,0) | C13: =IFERROR(B13/B$5,0) | D13: =IFERROR(D7-D9-D10,0) | E13: =IFERROR(D13/D$5,0) | F13: =IFERROR((D13-B13)/B13,0) | G13: =IFERROR(G7-G9-G10,0) | H13: =IFERROR(G13/G$5,0) | I13: =IFERROR((G13-D13)/D13,0) | J13: =IFERROR(AVERAGE(B13,D13,G13),0)
A14: (=) UTILIDAD OPERATIVA (EBIT) | B14: =IFERROR(B13-B11-B12,0) | C14: =IFERROR(B14/B$5,0) | D14: =IFERROR(D13-D11-D12,0) | E14: =IFERROR(D14/D$5,0) | F14: =IFERROR((D14-B14)/B14,0) | G14: =IFERROR(G13-G11-G12,0) | H14: =IFERROR(G14/G$5,0) | I14: =IFERROR((G14-D14)/D14,0) | J14: =IFERROR(AVERAGE(B14,D14,G14),0)
C15: =IFERROR(B15/B$5,0) | E15: =IFERROR(D15/D$5,0) | F15: =IFERROR((D15-B15)/B15,0) | H15: =IFERROR(G15/G$5,0) | I15: =IFERROR((G15-D15)/D15,0) | J15: =IFERROR(AVERAGE(B15,D15,G15),0)
A16: (+) Otros Ingresos | B16: 200 | C16: =IFERROR(B16/B$5,0) | D16: 250 | E16: =IFERROR(D16/D$5,0) | F16: =IFERROR((D16-B16)/B16,0) | G16: 300 | H16: =IFERROR(G16/G$5,0) | I16: =IFERROR((G16-D16)/D16,0) | J16: =IFERROR(AVERAGE(B16,D16,G16),0)
A17: (-) Otros Gastos | B17: 150 | C17: =IFERROR(B17/B$5,0) | D17: 180 | E17: =IFERROR(D17/D$5,0) | F17: =IFERROR((D17-B17)/B17,0) | G17: 200 | H17: =IFERROR(G17/G$5,0) | I17: =IFERROR((G17-D17)/D17,0) | J17: =IFERROR(AVERAGE(B17,D17,G17),0)
A18: (-) Gastos Financieros | B18: 300 | C18: =IFERROR(B18/B$5,0) | D18: 350 | E18: =IFERROR(D18/D$5,0) | F18: =IFERROR((D18-B18)/B18,0) | G18: 400 | H18: =IFERROR(G18/G$5,0) | I18: =IFERROR((G18-D18)/D18,0) | J18: =IFERROR(AVERAGE(B18,D18,G18),0)
A19: (=) UTILIDAD ANTES DE IMPUESTOS (UAI) | B19: =IFERROR(B14+B16-B17-B18,0) | C19: =IFERROR(B19/B$5,0) | D19: =IFERROR(D14+D16-D17-D18,0) | E19: =IFERROR(D19/D$5,0) | F19: =IFERROR((D19-B19)/B19,0) | G19: =IFERROR(G14+G16-G17-G18,0) | H19: =IFERROR(G19/G$5,0) | I19: =IFERROR((G19-D19)/D19,0) | J19: =IFERROR(AVERAGE(B19,D19,G19),0)
C20: =IFERROR(B20/B$5,0) | E20: =IFERROR(D20/D$5,0) | F20: =IFERROR((D20-B20)/B20,0) | H20: =IFERROR(G20/G$5,0) | I20: =IFERROR((G20-D20)/D20,0) | J20: =IFERROR(AVERAGE(B20,D20,G20),0)
A21: (-) Impuesto de Renta | B21: =IFERROR(B19*0.35,0) | C21: =IFERROR(B21/B$5,0) | D21: =IFERROR(D19*0.35,0) | E21: =IFERROR(D21/D$5,0) | F21: =IFERROR((D21-B21)/B21,0) | G21: =IFERROR(G19*0.35,0) | H21: =IFERROR(G21/G$5,0) | I21: =IFERROR((G21-D21)/D21,0) | J21: =IFERROR(AVERAGE(B21,D21,G21),0)
A22: (=) UTILIDAD NETA | B22: =IFERROR(B19-B21,0) | C22: =IFERROR(B22/B$5,0) | D22: =IFERROR(D19-D21,0) | E22: =IFERROR(D22/D$5,0) | F22: =IFERROR((D22-B22)/B22,0) | G22: =IFERROR(G19-G21,0) | H22: =IFERROR(G22/G$5,0) | I22: =IFERROR((G22-D22)/D22,0) | J22: =IFERROR(AVERAGE(B22,D22,G22),0)

Sheet ESF
A1: ESTADO DE SITUACIÓN FINANCIERA (BALANCE GENERAL)
A4: CONCEPTO | B4: Año 2022 | C4: AV% | D4: Año 2023 | E4: AV% | F4: AH% | G4: Año 2024 | H4: AV% | I4: AH%
A5: ACTIVOS
A7: ACTIVOS CORRIENTES:
A8: Efectivo y Equivalentes | B8: 3000 | C8: =IFERROR(B8/B$23,0) | D8: 3300 | E8: =IFERROR(D8/D$23,0) | F8: =IFERROR((D8-B8)/B8,0) | G8: 3696 | H8: =IFERROR(G8/G$23,0) | I8: =IFERROR((G8-D8)/D8,0)
A9: Cuentas por Cobrar Comerciales (Clientes) | B9: 2500 | C9: =IFERROR(B9/B$23,0) | D9: 2750 | E9: =IFERROR(D9/D$23,0) | F9: =IFERROR((D9-B9)/B9,0) | G9: 3080 | H9: =IFERROR(G9/G$23,0) | I9: =IFERROR((G9-D9)/D9,0)
A10: Cuentas por Cobrar a Socios/Accionistas | B10: 500 | C10: =IFERROR(B10/B$23,0) | D10: 550 | E10: =IFERROR(D10/D$23,0) | F10: =IFERROR((D10-B10)/B10,0) | G10: 616 | H10: =IFERROR(G10/G$23,0) | I10: =IFERROR((G10-D10)/D10,0)
A11: Inventarios | B11: 2000 | C11: =IFERROR(B11/B$23,0) | D11: 2200 | E11: =IFERROR(D11/D$23,0) | F11: =IFERROR((D11-B11)/B11,0) | G11: 2464 | H11: =IFERROR(G11/G$23,0) | I11: =IFERROR((G11-D11)/D11,0)
A12: Activos por Impuestos Corrientes | B12: 300 | C12: =IFERROR(B12/B$23,0) | D12: 330 | E12: =IFERROR(D12/D$23,0) | F12: =IFERROR((D12-B12)/B12,0) | G12: 369.6 | H12: =IFERROR(G12/G$23,0) | I12: =IFERROR((G12-D12)/D12,0)
A13: Otros Activos Corrientes | B13: 200 | C13: =IFERROR(B13/B$23,0) | D13: 220 | E13: =IFERROR(D13/D$23,0) | F13: =IFERROR((D13-B13)/B13,0) | G13: 246.4 | H13: =IFERROR(G13/G$23,0) | I13: =IFERROR((G13-D13)/D13,0)
A14: TOTAL ACTIVOS CORRIENTES | B14: =IFERROR(SUM(B8:B13),0) | C14: =IFERROR(B14/B$23,0) | D14: =IFERROR(SUM(D8:D13),0) | E14: =IFERROR(D14/D$23,0) | F14: =IFERROR((D14-B14)/B14,0) | G14: =IFERROR(SUM(G8:G13),0) | H14: =IFERROR(G14/G$23,0) | I14: =IFERROR((G14-D14)/D14,0)
C15: =IFERROR(B15/B$23,0) | E15: =IFERROR(D15/D$23,0) | F15: =IFERROR((D15-B15)/B15,0) | H15: =IFERROR(G15/G$23,0) | I15: =IFERROR((G15-D15)/D15,0)
A16: ACTIVOS NO CORRIENTES: | C16: =IFERROR(B16/B$23,0) | E16: =IFERROR(D16/D$23,0) | F16: =IFERROR((D16-B16)/B16,0) | H16: =IFERROR(G16/G$23,0) | I16: =IFERROR((G16-D16)/D16,0)
A17: Propiedades, Planta y Equipo (neto) | B17: 8000 | C17: =IFERROR(B17/B$23,0) | D17: 8800 | E17: =IFERROR(D17/D$23,0) | F17: =IFERROR((D17-B17)/B17,0) | G17: 9856 | H17: =IFERROR(G17/G$23,0) | I17: =IFERROR((G17-D17)/D17,0)
A18: Propiedades de Inversión | B18: 1000 | C18: =IFERROR(B18/B$23,0) | D18: 1100 | E18: =IFERROR(D18/D$23,0) | F18: =IFERROR((D18-B18)/B18,0) | G18: 1232 | H18: =IFERROR(G18/G$23,0) | I18: =IFERROR((G18-D18)/D18,0)
A19: Intangibles | B19: 500 | C19: =IFERROR(B19/B$23,0) | D19: 550 | E19: =IFERROR(D19/D$23,0) | F19: =IFERROR((D19-B19)/B19,0) | G19: 616 | H19: =IFERROR(G19/G$23,0) | I19: =IFERROR((G19-D19)/D19,0)
A20: Otros Activos No Corrientes | B20: 300 | C20: =IFERROR(B20/B$23,0) | D20: 330 | E20: =IFERROR(D20/D$23,0) | F20: =IFERROR((D20-B20)/B20,0) | G20: 369.6 | H20: =IFERROR(G20/G$23,0) | I20: =IFERROR((G20-D20)/D20,0)
A21: TOTAL ACTIVOS NO CORRIENTES | B21: =IFERROR(SUM(B17:B20),0) | C21: =IFERROR(B21/B$23,0) | D21: =IFERROR(SUM(D17:D20),0) | E21: =IFERROR(D21/D$23,0) | F21: =IFERROR((D21-B21)/B21,0) | G21: =IFERROR(SUM(G17:G20),0) | H21: =IFERROR(G21/G$23,0) | I21: =IFERROR((G21-D21)/D21,0)
C22: =IFERROR(B22/B$23,0) | E22: =IFERROR(D22/D$23,0) | F22: =IFERROR((D22-B22)/B22,0) | H22: =IFERROR(G22/G$23,0) | I22: =IFERROR((G22-D22)/D22,0)
A23: TOTAL ACTIVOS | B23: =IFERROR(B14+B21,0) | C23: =IFERROR(B23/B$23,0) | D23: =IFERROR(D14+D21,0) | E23: =IFERROR(D23/D$23,0) | F23: =IFERROR((D23-B23)/B23,0) | G23: =IFERROR(G14+G21,0) | H23: =IFERROR(G23/G$23,0) | I23: =IFERROR((G23-D23)/D23,0)
C24: =IFERROR(B24/B$23,0) | E24: =IFERROR(D24/D$23,0) | F24: =IFERROR((D24-B24)/B24,0) | H24: =IFERROR(G24/G$23,0) | I24: =IFERROR((G24-D24)/D24,0)
C25: =IFERROR(B25/B$23,0) | E25: =IFERROR(D25/D$23,0) | F25: =IFERROR((D25-B25)/B25,0) | H25: =IFERROR(G25/G$23,0) | I25: =IFERROR((G25-D25)/D25,0)
A26: PASIVOS | C26: =IFERROR(B26/B$23,0) | E26: =IFERROR(D26/D$23,0) | F26: =IFERROR((D26-B26)/B26,0) | H26: =IFERROR(G26/G$23,0) | I26: =IFERROR((G26-D26)/D26,0)
C27: =IFERROR(B27/B$23,0) | E27: =IFERROR(D27/D$23,0) | F27: =IFERROR((D27-B27)/B27,0) | H27: =IFERROR(G27/G$23,0) | I27: =IFERROR((G27-D27)/D27,0)
A28: PASIVOS CORRIENTES: | C28: =IFERROR(B28/B$23,0) | E28: =IFERROR(D28/D$23,0) | F28: =IFERROR((D28-B28)/B28,0) | H28: =IFERROR(G28/G$23,0) | I28: =IFERROR((G28-D28)/D28,0)
A29: Obligaciones Financieras Corto Plazo | B29: 1500 | C29: =IFERROR(B29/B$23,0) | D29: 1650 | E29: =IFERROR(D29/D$23,0) | F29: =IFERROR((D29-B29)/B29,0) | G29: 1848 | H29: =IFERROR(G29/G$23,0) | I29: =IFERROR((G29-D29)/D29,0)
A30: Cuentas por Pagar Comerciales (Proveedores) | B30: 1800 | C30: =IFERROR(B30/B$23,0) | D30: 1980 | E30: =IFERROR(D30/D$23,0) | F30: =IFERROR((D30-B30)/B30,0) | G30: 2217.6 | H30: =IFERROR(G30/G$23,0) | I30: =IFERROR((G30-D30)/D30,0)
A31: Otras Cuentas por Pagar (Costos y Gastos) | B31: 600 | C31: =IFERROR(B31/B$23,0) | D31: 660 | E31: =IFERROR(D31/D$23,0) | F31: =IFERROR((D31-B31)/B31,0) | G31: 739.2 | H31: =IFERROR(G31/G$23,0) | I31: =IFERROR((G31-D31)/D31,0)
A32: Pasivos Estimados y Provisiones | B32: 200 | C32: =IFERROR(B32/B$23,0) | D32: 220 | E32: =IFERROR(D32/D$23,0) | F32: =IFERROR((D32-B32)/B32,0) | G32: 246.4 | H32: =IFERROR(G32/G$23,0) | I32: =IFERROR((G32-D32)/D32,0)
A33: Dividendos por Pagar | B33: 0 | C33: =IFERROR(B33/B$23,0) | E33: =IFERROR(D33/D$23,0) | F33: =IFERROR((D33-B33)/B33,0) | H33: =IFERROR(G33/G$23,0) | I33: =IFERROR((G33-D33)/D33,0)
A34: Impuestos Corrientes por Pagar | B34: 150 | C34: =IFERROR(B34/B$23,0) | D34: 165 | E34: =IFERROR(D34/D$23,0) | F34: =IFERROR((D34-B34)/B34,0) | G34: 184.8 | H34: =IFERROR(G34/G$23,0) | I34: =IFERROR((G34-D34)/D34,0)
A35: Beneficios a Empleados | B35: 400 | C35: =IFERROR(B35/B$23,0) | D35: 440 | E35: =IFERROR(D35/D$23,0) | F35: =IFERROR((D35-B35)/B35,0) | G35: 492.8 | H35: =IFERROR(G35/G$23,0) | I35: =IFERROR((G35-D35)/D35,0)
A36: Otros Pasivos Corrientes | B36: 100 | C36: =IFERROR(B36/B$23,0) | D36: 110 | E36: =IFERROR(D36/D$23,0) | F36: =IFERROR((D36-B36)/B36,0) | G36: 123.2 | H36: =IFERROR(G36/G$23,0) | I36: =IFERROR((G36-D36)/D36,0)
A37: TOTAL PASIVOS CORRIENTES | B37: =IFERROR(SUM(B29:B36),0) | C37: =IFERROR(B37/B$23,0) | D37: =IFERROR(SUM(D29:D36),0) | E37: =IFERROR(D37/D$23,0) | F37: =IFERROR((D37-B37)/B37,0) | G37: =IFERROR(SUM(G29:G36),0) | H37: =IFERROR(G37/G$23,0) | I37: =IFERROR((G37-D37)/D37,0)
C38: =IFERROR(B38/B$23,0) | E38: =IFERROR(D38/D$23,0) | F38: =IFERROR((D38-B38)/B38,0) | H38: =IFERROR(G38/G$23,0) | I38: =IFERROR((G38-D38)/D38,0)
A39: PASIVOS NO CORRIENTES: | C39: =IFERROR(B39/B$23,0) | E39: =IFERROR(D39/D$23,0) | F39: =IFERROR((D39-B39)/B39,0) | H39: =IFERROR(G39/G$23,0) | I39: =IFERROR((G39-D39)/D39,0)
A40: Obligaciones Financieras Largo Plazo | B40: 3000 | C40: =IFERROR(B40/B$23,0) | D40: 3300 | E40: =IFERROR(D40/D$23,0) | F40: =IFERROR((D40-B40)/B40,0) | G40: 3696 | H40: =IFERROR(G40/G$23,0) | I40: =IFERROR((G40-D40)/D40,0)
A41: Cuentas por Pagar Largo Plazo | B41: 500 | C41: =IFERROR(B41/B$23,0) | D41: 550 | E41: =IFERROR(D41/D$23,0) | F41: =IFERROR((D41-B41)/B41,0) | G41: 616 | H41: =IFERROR(G41/G$23,0) | I41: =IFERROR((G41-D41)/D41,0)
A42: Otros Pasivos No Corrientes | B42: 200 | C42: =IFERROR(B42/B$23,0) | D42: 220 | E42: =IFERROR(D42/D$23,0) | F42: =IFERROR((D42-B42)/B42,0) | G42: 246.4 | H42: =IFERROR(G42/G$23,0) | I42: =IFERROR((G42-D42)/D42,0)
A43: TOTAL PASIVOS NO CORRIENTES | B43: =IFERROR(SUM(B40:B42),0) | C43: =IFERROR(B43/B$23,0) | D43: =IFERROR(SUM(D40:D42),0) | E43: =IFERROR(D43/D$23,0) | F43: =IFERROR((D43-B43)/B43,0) | G43: =IFERROR(SUM(G40:G42),0) | H43: =IFERROR(G43/G$23,0) | I43: =IFERROR((G43-D43)/D43,0)
...

Sheet INDICADORES
A1: INDICADORES FINANCIEROS
A4: INDICADOR | B4: Fórmula | C4: 2022 | D4: 2023 | E4: Δ | F4: Δ% | G4: 2024 | H4: Δ | I4: Δ% | J4: Semáforo | K4: Benchmark | L4: vs Ind
A6: A. INDICADORES DE LIQUIDEZ
A7: Razón Corriente | B7: Activo Corriente / Pasivo Corriente | C7: =IFERROR(ESF!B14/ESF!B37,0) | D7: =IFERROR(ESF!D14/ESF!D37,0) | E7: =D7-C7 | F7: =IFERROR((D7-C7)/C7,0) | G7: =IFERROR(ESF!G14/ESF!G37,0) | H7: =G7-D7 | I7: =IFERROR((G7-D7)/D7,0) | J7: =IF(G7>=1.5,"🟢 Óptimo",IF(G7>=1,"🟡 Aceptable","🔴 Crítico"))
A8: Prueba Ácida | B8: (Activo Corriente - Inventarios) / Pasivo Corriente | C8: =IFERROR((ESF!B14-ESF!B11)/ESF!B37,0) | D8: =IFERROR((ESF!D14-ESF!D11)/ESF!D37,0) | E8: =D8-C8 | F8: =IFERROR((D8-C8)/C8,0) | G8: =IFERROR((ESF!G14-ESF!G11)/ESF!G37,0) | H8: =G8-D8 | I8: =IFERROR((G8-D8)/D8,0) | J8: =IF(G8>=1,"🟢 Óptimo",IF(G8>=0.8,"🟡 Aceptable","🔴 Crítico"))
A9: Capital de Trabajo (KT) | B9: Activo Corriente - Pasivo Corriente | C9: =IFERROR(ESF!B14-ESF!B37,0) | D9: =IFERROR(ESF!D14-ESF!D37,0) | E9: =D9-C9 | F9: =IFERROR((D9-C9)/C9,0) | G9: =IFERROR(ESF!G14-ESF!G37,0) | H9: =G9-D9 | I9: =IFERROR((G9-D9)/D9,0) | J9: =IF(G9>0,"🟢 Positivo","🔴 Negativo")
A10: Capital de Trabajo Neto Operativo (KTNO) | B10: CxC Clientes + Inventarios - Proveedores | C10: =IFERROR(ESF!B9+ESF!B11-ESF!B30,0) | D10: =IFERROR(ESF!D9+ESF!D11-ESF!D30,0) | E10: =D10-C10 | F10: =IFERROR((D10-C10)/C10,0) | G10: =IFERROR(ESF!G9+ESF!G11-ESF!G30,0) | H10: =G10-D10 | I10: =IFERROR((G10-D10)/D10,0)
A11: Productividad del KT (PKT) | B11: KT / Ventas | C11: =IFERROR(C9/EERR!B5,0) | D11: =IFERROR(D9/EERR!D5,0) | E11: =D11-C11 | F11: =IFERROR((D11-C11)/C11,0) | G11: =IFERROR(G9/EERR!G5,0) | H11: =G11-D11 | I11: =IFERROR((G11-D11)/D11,0)
A12: Productividad del KTNO (PKTNO) | B12: KTNO / Ventas | C12: =IFERROR(C10/EERR!B5,0) | D12: =IFERROR(D10/EERR!D5,0) | E12: =D12-C12 | F12: =IFERROR((D12-C12)/C12,0) | G12: =IFERROR(G10/EERR!G5,0) | H12: =G12-D12 | I12: =IFERROR((G12-D12)/D12,0)
A13: Solvencia | B13: Activo Total / Pasivo Total | C13: =IFERROR(ESF!B23/ESF!B45,0) | D13: =IFERROR(ESF!D23/ESF!D45,0) | E13: =D13-C13 | F13: =IFERROR((D13-C13)/C13,0) | G13: =IFERROR(ESF!G23/ESF!G45,0) | H13: =G13-D13 | I13: =IFERROR((G13-D13)/D13,0) | J13: =IF(G13>=2,"🟢 Óptimo",IF(G13>=1,"🟡 Aceptable","🔴 Crítico"))
A15: B. INDICADORES DE RENTABILIDAD
A16: Margen Bruto | B16: Utilidad Bruta / Ventas | C16: =IFERROR(EERR!B7/EERR!B5,0) | D16: =IFERROR(EERR!D7/EERR!D5,0) | E16: =D16-C16 | F16: =IFERROR((D16-C16)/C16,0) | G16: =IFERROR(EERR!G7/EERR!G5,0) | H16: =G16-D16 | I16: =IFERROR((G16-D16)/D16,0) | J16: =IF(G16>=0.3,"🟢 Óptimo",IF(G16>=0.2,"🟡 Aceptable","🔴 Bajo"))
A17: Margen EBITDA | B17: EBITDA / Ventas | C17: =IFERROR(EERR!B13/EERR!B5,0) | D17: =IFERROR(EERR!D13/EERR!D5,0) | E17: =D17-C17 | F17: =IFERROR((D17-C17)/C17,0) | G17: =IFERROR(EERR!G13/EERR!G5,0) | H17: =G17-D17 | I17: =IFERROR((G17-D17)/D17,0) | J17: =IF(G17>=0.15,"🟢 Óptimo",IF(G17>=0.1,"🟡 Aceptable","🔴 Bajo"))
A18: Margen Operativo | B18: Utilidad Operativa / Ventas | C18: =IFERROR(EERR!B14/EERR!B5,0) | D18: =IFERROR(EERR!D14/EERR!D5,0) | E18: =D18-C18 | F18: =IFERROR((D18-C18)/C18,0) | G18: =IFERROR(EERR!G14/EERR!G5,0) | H18: =G18-D18 | I18: =IFERROR((G18-D18)/D18,0) | J18: =IF(G18>=0.1,"🟢 Óptimo",IF(G18>=0.05,"🟡 Aceptable","🔴 Bajo"))
A19: Margen Neto | B19: Utilidad Neta / Ventas | C19: =IFERROR(EERR!B22/EERR!B5,0) | D19: =IFERROR(EERR!D22/EERR!D5,0) | E19: =D19-C19 | F19: =IFERROR((D19-C19)/C19,0) | G19: =IFERROR(EERR!G22/EERR!G5,0) | H19: =G19-D19 | I19: =IFERROR((G19-D19)/D19,0) | J19: =IF(G19>=0.1,"🟢 Óptimo",IF(G19>=0.05,"🟡 Aceptable","🔴 Bajo"))
A20: ROA (Retorno sobre Activos) | B20: Utilidad Neta / Activos Totales | C20: =IFERROR(EERR!B22/ESF!B23,0) | D20: =IFERROR(EERR!D22/ESF!D23,0) | E20: =D20-C20 | F20: =IFERROR((D20-C20)/C20,0) | G20: =IFERROR(EERR!G22/ESF!G23,0) | H20: =G20-D20 | I20: =IFERROR((G20-D20)/D20,0) | J20: =IF(G20>=0.1,"🟢 Óptimo",IF(G20>=0.05,"🟡 Aceptable","🔴 Bajo"))
A21: ROE (Retorno sobre Patrimonio) | B21: Utilidad Neta / Patrimonio | C21: =IFERROR(EERR!B22/ESF!B54,0) | D21: =IFERROR(EERR!D22/ESF!D54,0) | E21: =D21-C21 | F21: =IFERROR((D21-C21)/C21,0) | G21: =IFERROR(EERR!G22/ESF!G54,0) | H21: =G21-D21 | I21: =IFERROR((G21-D21)/D21,0) | J21: =IF(G21>=0.15,"🟢 Óptimo",IF(G21>=0.1,"🟡 Aceptable","🔴 Bajo"))
A22: Tasa Efectiva de Tributación | B22: Impuestos / UAI | C22: =IFERROR(EERR!B21/EERR!B19,0) | D22: =IFERROR(EERR!D21/EERR!D19,0) | E22: =D22-C22 | F22: =IFERROR((D22-C22)/C22,0) | G22: =IFERROR(EERR!G21/EERR!G19,0) | H22: =G22-D22 | I22: =IFERROR((G22-D22)/D22,0)
A24: C. INDICADORES DE ENDEUDAMIENTO
A25: Nivel de Endeudamiento | B25: Pasivo Total / Activo Total | C25: =IFERROR(ESF!B45/ESF!B23,0) | D25: =IFERROR(ESF!D45/ESF!D23,0) | E25: =D25-C25 | F25: =IFERROR((D25-C25)/C25,0) | G25: =IFERROR(ESF!G45/ESF!G23,0) | H25: =G25-D25 | I25: =IFERROR((G25-D25)/D25,0) | J25: =IF(G25<=0.5,"🟢 Óptimo",IF(G25<=0.7,"🟡 Moderado","🔴 Alto"))
A26: Concentración Deuda Corto Plazo | B26: Pasivo Corriente / Pasivo Total | C26: =IFERROR(ESF!B37/ESF!B45,0) | D26: =IFERROR(ESF!D37/ESF!D45,0) | E26: =D26-C26 | F26: =IFERROR((D26-C26)/C26,0) | G26: =IFERROR(ESF!G37/ESF!G45,0) | H26: =G26-D26 | I26: =IFERROR((G26-D26)/D26,0)
A27: Deuda Financiera / Activos | B27: (Oblig. Financ. CP + LP) / Activos | C27: =IFERROR((ESF!B29+ESF!B40)/ESF!B23,0) | D27: =IFERROR((ESF!D29+ESF!D40)/ESF!D23,0) | E27: =D27-C27 | F27: =IFERROR((D27-C27)/C27,0) | G27: =IFERROR((ESF!G29+ESF!G40)/ESF!G23,0) | H27: =G27-D27 | I27: =IFERROR((G27-D27)/D27,0)
A28: Deuda / Patrimonio | B28: Pasivo Total / Patrimonio | C28: =IFERROR(ESF!B45/ESF!B54,0) | D28: =IFERROR(ESF!D45/ESF!D54,0) | E28: =D28-C28 | F28: =IFERROR((D28-C28)/C28,0) | G28: =IFERROR(ESF!G45/ESF!G54,0) | H28: =G28-D28 | I28: =IFERROR((G28-D28)/D28,0)
A29: Cobertura de Intereses | B29: EBIT / Gastos Financieros | C29: =IFERROR(EERR!B14/EERR!B18,0) | D29: =IFERROR(EERR!D14/EERR!D18,0) | E29: =D29-C29 | F29: =IFERROR((D29-C29)/C29,0) | G29: =IFERROR(EERR!G14/EERR!G18,0) | H29: =G29-D29 | I29: =IFERROR((G29-D29)/D29,0) | J29: =IF(G29>=5,"🟢 Óptimo",IF(G29>=2,"🟡 Aceptable","🔴 Crítico"))
A31: D. INDICADORES DE ACTIVIDAD/ROTACIÓN
A32: Rotación de Inventarios (veces) | B32: Costo de Ventas / Inventarios | C32: =IFERROR(EERR!B6/ESF!B11,0) | D32: =IFERROR(EERR!D6/ESF!D11,0) | E32: =D32-C32 | F32: =IFERROR((D32-C32)/C32,0) | G32: =IFERROR(EERR!G6/ESF!G11,0) | H32: =G32-D32 | I32: =IFERROR((G32-D32)/D32,0)
A33: Días de Inventario | B33: 365 / Rotación de Inventarios | C33: =IFERROR(365/C32,0) | D33: =IFERROR(365/D32,0) | E33: =D33-C33 | F33: =IFERROR((D33-C33)/C33,0) | G33: =IFERROR(365/G32,0) | H33: =G33-D33 | I33: =IFERROR((G33-D33)/D33,0)
A34: Rotación de Cartera (veces) | B34: Ventas / CxC Clientes | C34: =IFERROR(EERR!B5/ESF!B9,0) | D34: =IFERROR(EERR!D5/ESF!D9,0) | E34: =D34-C34 | F34: =IFERROR((D34-C34)/C34,0) | G34: =IFERROR(EERR!G5/ESF!G9,0) | H34: =G34-D34 | I34: =IFERROR((G34-D34)/D34,0)
A35: Días de Cartera | B35: 365 / Rotación de Cartera | C35: =IFERROR(365/C34,0) | D35: =IFERROR(365/D34,0) | E35: =D35-C35 | F35: =IFERROR((D35-C35)/C35,0) | G35: =IFERROR(365/G34,0) | H35: =G35-D35 | I35: =IFERROR((G35-D35)/D35,0)
A36: Rotación de Proveedores (veces) | B36: Costo de Ventas / Proveedores | C36: =IFERROR(EERR!B6/ESF!B30,0) | D36: =IFERROR(EERR!D6/ESF!D30,0) | E36: =D36-C36 | F36: =IFERROR((D36-C36)/C36,0) | G36: =IFERROR(EERR!G6/ESF!G30,0) | H36: =G36-D36 | I36: =IFERROR((G36-D36)/D36,0)
A37: Días de Proveedores | B37: 365 / Rotación de Proveedores | C37: =IFERROR(365/C36,0) | D37: =IFERROR(365/D36,0) | E37: =D37-C37 | F37: =IFERROR((D37-C37)/C37,0) | G37: =IFERROR(365/G36,0) | H37: =G37-D37 | I37: =IFERROR((G37-D37)/D37,0)
A38: Ciclo Operativo | B38: Días Inventario + Días Cartera | C38: =IFERROR(C33+C35,0) | D38: =IFERROR(D33+D35,0) | E38: =D38-C38 | F38: =IFERROR((D38-C38)/C38,0) | G38: =IFERROR(G33+G35,0) | H38: =G38-D38 | I38: =IFERROR((G38-D38)/D38,0)
A39: Ciclo de Conversión de Efectivo | B39: Ciclo Operativo - Días Proveedores | C39: =IFERROR(C38-C37,0) | D39: =IFERROR(D38-D37,0) | E39: =D39-C39 | F39: =IFERROR((D39-C39)/C39,0) | G39: =IFERROR(G38-G37,0) | H39: =G39-D39 | I39: =IFERROR((G39-D39)/D39,0) | J39: =IF(G39<=30,"🟢 Óptimo",IF(G39<=60,"🟡 Aceptable","🔴 Alto"))
A40: GAP Financiero | B40: Días de financiación requerida | C40: =C39 | D40: =D39 | E40: =D40-C40 | F40: =IFERROR((D40-C40)/C40,0) | G40: =G39 | H40: =G40-D40 | I40: =IFERROR((G40-D40)/D40,0)
A42: E. INDICADORES DE INVERSIÓN
A43: Depreciación / PPE | B43: Depreciación / Propiedad, Planta y Equipo
A44: CAPEX / Activos Fijos | B44: CAPEX / Activos Fijos
A45: Variación % en Ventas | B45: Crecimiento en Ventas
A46: Variación % en EBITDA | B46: Crecimiento en EBITDA

Sheet PUNTO EQUILIBRIO
A1: ANÁLISIS DE PUNTO DE EQUILIBRIO
A3: DATOS DE ENTRADA
A4: Precio de Venta Promedio Unitario: | C4: $
A5: Costo Variable Unitario: | C5: $
A7: COSTOS FIJOS TOTALES:
A8: Gastos Administrativos: | C8: $
A9: Gastos de Ventas: | C9: $
A10: Gastos Financieros: | C10: $
A11: TOTAL COSTOS FIJOS: | C11: $
B12: =IFERROR(SUM(B9:B11),0)
A13: RESULTADOS CALCULADOS
A14: Margen de Contribución Unitario: | B14: =IFERROR(B5-B6,0)
A15: Margen de Contribución %: | B15: =IFERROR(B14/B5,0)
A16: Punto de Equilibrio (unidades): | B16: =IFERROR(B12/B14,0)
A17: Punto de Equilibrio (valor $): | B17: =IFERROR(B12/B15,0)
A18: Ventas Actuales (unidades): | B18: =EERR!G5
A19: Margen de Seguridad: | B19: =IFERROR((B18-B17)/B18,0)
A21: ANÁLISIS DE SENSIBILIDAD
A22: Variación del Precio de Venta
A23: Escenario | B23: Variación | C23: Nuevo Precic PE Unidades | D23: PE Unidades | E23: PE Valor ($) | F23: Impacto
A24: Precio -15% | B24: -15% | C24: =IFERROR($B$4*(1+B24),0) | D24: =IFERROR($B$11/(C24-$B$5),0) | E24: =IFERROR(D24*C24,0) | F24: =IFERROR((D24-$B$16)/$B$16,0)
A25: Precio -10% | B25: -10% | C25: =IFERROR($B$4*(1+B25),0) | D25: =IFERROR($B$11/(C25-$B$5),0) | E25: =IFERROR(D25*C25,0) | F25: =IFERROR((D25-$B$16)/$B$16,0)
A26: Precio -5% | B26: -5% | C26: =IFERROR($B$4*(1+B26),0) | D26: =IFERROR($B$11/(C26-$B$5),0) | E26: =IFERROR(D26*C26,0) | F26: =IFERROR((D26-$B$16)/$B$16,0)
A27: Precio Base | B27: -15% | C27: =IFERROR($B$4*(1+B27),0) | D27: =IFERROR($B$11/(C27-$B$5),0) | E27: =IFERROR(D27*C27,0) | F27: =IFERROR((D27-$B$16)/$B$16,0)
A28: Precio +5% | B28: -10% | C28: =IFERROR($B$4*(1+B28),0) | D28: =IFERROR($B$11/(C28-$B$5),0) | E28: =IFERROR(D28*C28,0) | F28: =IFERROR((D28-$B$16)/$B$16,0)
A29: Precio +10% | B29: -5% | C29: =IFERROR($B$4*(1+B29),0) | D29: =IFERROR($B$11/(C29-$B$5),0) | E29: =IFERROR(D29*C29,0) | F29: =IFERROR((D29-$B$16)/$B$16,0)
A30: Precio +15% | B30: 0% | C30: =IFERROR($B$4*(1+B30),0) | D30: =IFERROR($B$11/(C30-$B$5),0) | E30: =IFERROR(D30*C30,0) | F30: =IFERROR((D30-$B$16)/$B$16,0)
B31: 5% | C31: =IFERROR(B5*(1+0.05),0) | D31: =IFERROR(B12/(C31-B6),0) | E31: =IFERROR(D31*C31,0) | F31: =IFERROR((D31-B16)/B16,0)
B32: 10% | C32: =IFERROR(B5*(1+0.1),0) | D32: =IFERROR(B12/(C32-B6),0) | E32: =IFERROR(D32*C32,0) | F32: =IFERROR((D32-B16)/B16,0)
B33: 15% | C33: =IFERROR(B5*(1+0.15),0) | D33: =IFERROR(B12/(C33-B6),0) | E33: =IFERROR(D33*C33,0) | F33: =IFERROR((D33-B16)/B16,0)

Sheet PROYECCIONES
A1: PROYECCIONES FINANCIERAS A 5-7 AÑOS
A3: SUPUESTOS DE PROYECCIÓN
A4: Tasa de Crecimiento de Ventas (anual): | B4: %
A5: Margen Bruto Esperado: | B5: 0.1
A6: Gastos Administrativos (% de Ventas): | B6: =INDICADORES!G16
A7: Gastos de Ventas (% de Ventas): | B7: 0.15
A8: Tasa de Interés de Deuda: | B8: 0.1
A9: Tasa de Impuesto de Renta: | B9: 35%
A10: Días de Cartera Objetivo: | B10: días
A11: Días de Inventario Objetivo: | B11: días
A12: Días de Proveedores Objetivo: | B12: días
A13: CAPEX Anual Proyectado: | B13: $
A16: ESTADO DE RESULTADOS PROYECTADO
A17: CONCEPTO | B17: Año 2025 | C17: Año 2026 | D17: Año 2027 | E17: Año 2028 | F17: Año 2029 | G17: Año 2030 | H17: Año 2031
A18: Ingresos (Ventas) | B18: =IFERROR(EERR!G5*(1+$B$5),0) | C18: =IFERROR(B18*(1+$B$5),0) | D18: =IFERROR(C18*(1+$B$5),0) | E18: =IFERROR(D18*(1+$B$5),0) | F18: =IFERROR(E18*(1+$B$5),0) | G18: =IFERROR(F18*(1+$B$5),0) | H18: =IFERROR(G18*(1+$B$5),0)
A19: (-) Costo de Ventas | B19: =IFERROR(B18*(1-$B$6),0) | C19: =IFERROR(C18*(1-$B$6),0) | D19: =IFERROR(D18*(1-$B$6),0) | E19: =IFERROR(E18*(1-$B$6),0) | F19: =IFERROR(F18*(1-$B$6),0) | G19: =IFERROR(G18*(1-$B$6),0) | H19: =IFERROR(H18*(1-$B$6),0)
A20: Utilidad Bruta | B20: =IFERROR(B18-B19,0) | C20: =IFERROR(C18-C19,0) | D20: =IFERROR(D18-D19,0) | E20: =IFERROR(E18-E19,0) | F20: =IFERROR(F18-F19,0) | G20: =IFERROR(G18-G19,0) | H20: =IFERROR(H18-H19,0)
B21: =IFERROR(B20*(1-$B$6),0) | C21: =IFERROR(C20*(1-$B$6),0) | D21: =IFERROR(D20*(1-$B$6),0) | E21: =IFERROR(E20*(1-$B$6),0) | F21: =IFERROR(F20*(1-$B$6),0) | G21: =IFERROR(G20*(1-$B$6),0) | H21: =IFERROR(H20*(1-$B$6),0)
A22: (-) Gastos Administrativos | B22: =IFERROR(B18*$B$7,0) | C22: =IFERROR(C18*$B$7,0) | D22: =IFERROR(D18*$B$7,0) | E22: =IFERROR(E18*$B$7,0) | F22: =IFERROR(F18*$B$7,0) | G22: =IFERROR(G18*$B$7,0) | H22: =IFERROR(H18*$B$7,0)
A23: (-) Gastos de Ventas | B23: =IFERROR(B18*$B$8,0) | C23: =IFERROR(C18*$B$8,0) | D23: =IFERROR(D18*$B$8,0) | E23: =IFERROR(E18*$B$8,0) | F23: =IFERROR(F18*$B$8,0) | G23: =IFERROR(G18*$B$8,0) | H23: =IFERROR(H18*$B$8,0)
A24: (-) Depreciación | B24: =IFERROR(B18*0.02,0) | C24: =IFERROR(C18*0.02,0) | D24: =IFERROR(D18*0.02,0) | E24: =IFERROR(E18*0.02,0) | F24: =IFERROR(F18*0.02,0) | G24: =IFERROR(G18*0.02,0) | H24: =IFERROR(H18*0.02,0)
A25: EBITDA | B25: =IFERROR(B20-B22-B23,0) | C25: =IFERROR(C20-C22-C23,0) | D25: =IFERROR(D20-D22-D23,0) | E25: =IFERROR(E20-E22-E23,0) | F25: =IFERROR(F20-F22-F23,0) | G25: =IFERROR(G20-G22-G23,0) | H25: =IFERROR(H20-H22-H23,0)
A26: Utilidad Operativa (EBIT) | B26: =IFERROR(B25-B24,0) | C26: =IFERROR(C25-C24,0) | D26: =IFERROR(D25-D24,0) | E26: =IFERROR(E25-E24,0) | F26: =IFERROR(F25-F24,0) | G26: =IFERROR(G25-G24,0) | H26: =IFERROR(H25-H24,0)
B27: =IFERROR(B22-B24-B25,0) | C27: =IFERROR(C22-C24-C25,0) | D27: =IFERROR(D22-D24-D25,0) | E27: =IFERROR(E22-E24-E25,0) | F27: =IFERROR(F22-F24-F25,0) | G27: =IFERROR(G22-G24-G25,0) | H27: =IFERROR(H22-H24-H25,0)
A28: (-) Gastos Financieros | B28: =IFERROR(B18*0.02,0) | C28: =IFERROR(C18*0.02,0) | D28: =IFERROR(D18*0.02,0) | E28: =IFERROR(E18*0.02,0) | F28: =IFERROR(F18*0.02,0) | G28: =IFERROR(G18*0.02,0) | H28: =IFERROR(H18*0.02,0)
A29: Utilidad Antes de Impuestos | B29: =IFERROR(B26-B28,0) | C29: =IFERROR(C26-C28,0) | D29: =IFERROR(D26-D28,0) | E29: =IFERROR(E26-E28,0) | F29: =IFERROR(F26-F28,0) | G29: =IFERROR(G26-G28,0) | H29: =IFERROR(H26-H28,0)
A30: (-) Impuesto de Renta | B30: =IFERROR(B29*0.35,0) | C30: =IFERROR(C29*0.35,0) | D30: =IFERROR(D29*0.35,0) | E30: =IFERROR(E29*0.35,0) | F30: =IFERROR(F29*0.35,0) | G30: =IFERROR(G29*0.35,0) | H30: =IFERROR(H29*0.35,0)
A31: UTILIDAD NETA | B31: =IFERROR(B29-B30,0) | C31: =IFERROR(C29-C30,0) | D31: =IFERROR(D29-D30,0) | E31: =IFERROR(E29-E30,0) | F31: =IFERROR(F29-F30,0) | G31: =IFERROR(G29-G30,0) | H31: =IFERROR(H29-H30,0)
B32: =IFERROR(B31*0.35,0) | C32: =IFERROR(C31*0.35,0) | D32: =IFERROR(D31*0.35,0) | E32: =IFERROR(E31*0.35,0) | F32: =IFERROR(F31*0.35,0) | G32: =IFERROR(G31*0.35,0) | H32: =IFERROR(H31*0.35,0)
B33: =IFERROR(B31-B32,0) | C33: =IFERROR(C31-C32,0) | D33: =IFERROR(D31-D32,0) | E33: =IFERROR(E31-E32,0) | F33: =IFERROR(F31-F32,0) | G33: =IFERROR(G31-G32,0) | H33: =IFERROR(H31-H32,0)

Sheet VALORACIÓN
A1: VALORACIÓN DE LA EMPRESA
A3: CÁLCULO DEL WACC (Costo Promedio Ponderado de Capital)
A4: Costo del Patrimonio (Ke) - CAPM:
A5: Tasa Libre de Riesgo (Rf): | B5: %
A6: Beta del Sector: | B6: =CONFIGURACIÓN!B16
A7: Prima de Riesgo de Mercado: | B7: 1.2
A8: Prima de Riesgo País Colombia: | B8: 0.08
A9: Ke = Rf + β × (Rm - Rf) + Riesgo País | B9: 0.025
B10: =IFERROR(B6+B7*B8+B9,0)
A11: Costo de la Deuda (Kd): | B11: %
A12: Tasa de Impuesto: | B12: 0.12
A13: Kd después de impuestos: | B13: 0.35
B14: =IFERROR(B12*(1-B13),0)
A15: Estructura de Capital:
A16: Patrimonio (E): | B16: $
A17: Deuda (D): | B17: =ESF!G54
A18: Total (E+D): | B18: =ESF!G45
A19: % Patrimonio: | B19: =IFERROR(B17+B18,0)
A20: % Deuda: | B20: =IFERROR(B17/B19,0)
B21: =IFERROR(B18/B19,0)
A22: WACC = Ke × (E/V) + Kd × (1-T) × (D/V)
A23: WACC CALCULADO: | B23: %
B24: =IFERROR(B10*B20+B14*B21,0)
A25: FLUJO DE CAJA LIBRE DESCONTADO
A27: Año | B27: FCF | C27: Factor Desc. | D27: FCF Descontado | E27: FCF Acum.
B28: 1 | C28: 2 | D28: 3 | E28: 4 | F28: 5 | G28: 6 | H28: 7
B29: =IFERROR(PROYECCIONES!B26*0.65,0) | C29: =IFERROR(PROYECCIONES!C26*0.65,0) | D29: =IFERROR(PROYECCIONES!D26*0.65,0) | E29: =IFERROR(PROYECCIONES!E26*0.65,0) | F29: =IFERROR(PROYECCIONES!F26*0.65,0) | G29: =IFERROR(PROYECCIONES!G26*0.65,0) | H29: =IFERROR(PROYECCIONES!H26*0.65,0)
B30: =IFERROR(1/((1+$B$24)^1),0) | C30: =IFERROR(1/((1+$B$24)^2),0) | D30: =IFERROR(1/((1+$B$24)^3),0) | E30: =IFERROR(1/((1+$B$24)^4),0) | F30: =IFERROR(1/((1+$B$24)^5),0) | G30: =IFERROR(1/((1+$B$24)^6),0) | H30: =IFERROR(1/((1+$B$24)^7),0)
B31: =IFERROR(B29*B30,0) | C31: =IFERROR(C29*C30,0) | D31: =IFERROR(D29*D30,0) | E31: =IFERROR(E29*E30,0) | F31: =IFERROR(F29*F30,0) | G31: =IFERROR(G29*G30,0) | H31: =IFERROR(H29*H30,0)
B32: =IFERROR(1/((1+$B$24)^1),0) | C32: =IFERROR(1/((1+$B$24)^2),0) | D32: =IFERROR(1/((1+$B$24)^3),0) | E32: =IFERROR(1/((1+$B$24)^4),0) | F32: =IFERROR(1/((1+$B$24)^5),0) | G32: =IFERROR(1/((1+$B$24)^6),0) | H32: =IFERROR(1/((1+$B$24)^7),0)
A33: SUMA FCF Descontados: | B33: =IFERROR(SUM(B31:H31),0) | C33: =IFERROR(C31*C32,0) | D33: =IFERROR(D31*D32,0) | E33: =IFERROR(E31*E32,0) | F33: =IFERROR(F31*F32,0) | G33: =IFERROR(G31*G32,0) | H33: =IFERROR(H31*H32,0)
A35: Valor Terminal (Perpetuidad): | B35: =IFERROR(SUM(B33:H33),0) | C35: 2.5%
A36: Tasa de crecimiento perpetuo: | B36: 0.025
A37: VT = | B37: =IFERROR(H29*(1+B36)/(B24-B36),0)
A38: VT Descontado = | B38: =IFERROR(B37*H30,0) | C38: 0.025
B39: =IFERROR(B38*H32,0)
A40: VALOR TOTAL DE LA EMPRESA: | B40: =IFERROR(B33+B38,0)
B41: =IFERROR(B35+B39,0)

Sheet BENCHMARKS
A1: BENCHMARKS DE INDUSTRIA (Damodaran)
A2: Fuente: Aswath Damodaran - Stern School of Business, NYU
A4: Sector | B4: Margen Bruto | C4: Margen EBITDA | D4: Margen Neto | E4: ROE | F4: ROA | G4: Beta | H4: Razón Corriente | I4: Días Inv. | J4: EV/Sales | K4: EV/EBITDA
A5: Manufactura | B5: 28% | C5: 15% | D5: 8% | E5: 12% | F5: 6% | G5: 1.05 | H5: 1.8 | I5: 45 | J5: 1.2x | K5: 8.5x
A6: Servicios | B6: 45% | C6: 22% | D6: 12% | E6: 18% | F6: 9% | G6: 0.95 | H6: 1.5 | I6: 15 | J6: 2.0x | K6: 10.0x
A7: Comercio / Retail | B7: 25% | C7: 10% | D7: 5% | E7: 15% | F7: 7% | G7: 1.10 | H7: 1.6 | I7: 60 | J7: 0.8x | K7: 7.5x
A8: Tecnología / Software | B8: 75% | C8: 35% | D8: 18% | E8: 25% | F8: 12% | G8: 1.25 | H8: 2.5 | I8: 10 | J8: 5.0x | K8: 15.0x
A9: Agroindustria | B9: 22% | C9: 12% | D9: 6% | E9: 10% | F9: 5% | G9: 0.90 | H9: 1.7 | I9: 90 | J9: 1.0x | K9: 9.0x
A10: Salud / Healthcare | B10: 55% | C10: 25% | D10: 14% | E10: 20% | F10: 10% | G10: 0.85 | H10: 2.0 | I10: 30 | J10: 2.5x | K10: 12.0x
A11: Construcción | B11: 18% | C11: 8% | D11: 4% | E11: 12% | F11: 5% | G11: 1.15 | H11: 1.4 | I11: 75 | J11: 0.9x | K11: 8.0x
A14: COMPARACIÓN: EMPRESA VS INDUSTRIA
A16: Indicador | B16: Empresa | C16: Industria | D16: Brecha | E16: Semáforo | F16: Comentario
A17: Margen Bruto | B17: =INDICADORES!G16 | D17: =IFERROR(B17-C17,0) | E17: =IF(D17>0,"🟢 Por encima",IF(D17=0,"🟡 Igual","🔴 Por debajo"))
A18: Margen EBITDA | B18: =INDICADORES!G17 | D18: =IFERROR(B18-C18,0) | E18: =IF(D18>0,"🟢 Por encima",IF(D18=0,"🟡 Igual","🔴 Por debajo"))
A19: Margen Neto | B19: =INDICADORES!G19 | D19: =IFERROR(B19-C19,0) | E19: =IF(D19>0,"🟢 Por encima",IF(D19=0,"🟡 Igual","🔴 Por debajo"))
A20: ROE | B20: =INDICADORES!G21 | D20: =IFERROR(B20-C20,0) | E20: =IF(D20>0,"🟢 Por encima",IF(D20=0,"🟡 Igual","🔴 Por debajo"))
A21: ROA | B21: =INDICADORES!G20 | D21: =IFERROR(B21-C21,0) | E21: =IF(D21>0,"🟢 Por encima",IF(D21=0,"🟡 Igual","🔴 Por debajo"))
A22: Razón Corriente | B22: =INDICADORES!G7 | D22: =IFERROR(B22-C22,0) | E22: =IF(D22>0,"🟢 Por encima",IF(D22=0,"🟡 Igual","🔴 Por debajo"))
A23: Nivel Endeudamiento | B23: =INDICADORES!G25 | D23: =IFERROR(B23-C23,0) | E23: =IF(D23>0,"🟢 Por encima",IF(D23=0,"🟡 Igual","🔴 Por debajo"))

Sheet DIAGNÓSTICO
A1: DIAGNÓSTICO FINANCIERO AUTOMÁTICO | J1: =INDICADORES!G7
J2: =INDICADORES!G19
A3: =CONCATENATE("=== DIAGNÓSTICO FINANCIERO DE ",UPPER(CONFIGURACIÓN!B5)," ===") | J3: =INDICADORES!G25
A4: =CONCATENATE("Sector: ",CONFIGURACIÓN!B7) | J4: =INDICADORES!G21
A5: =CONCATENATE("Período analizado: 2022 - ",CONFIGURACIÓN!B11) | J5: =INDICADORES!G39
A6: =CONCATENATE("Fecha de elaboración: ",TEXT(TODAY(),"dd/mm/yyyy"))
A8: ═══════════════════════════════════════════════════════════════
A10: 1. RESUMEN EJECUTIVO
A11: ────────────────────────────────────────────────────────────
A13: [Generar automáticamente un párrafo de 3-4 oraciones resumiendo la situación general]
A16: 2. ANÁLISIS DE LIQUIDEZ
A17: ────────────────────────────────────────────────────────────
A19: 2.1 Razón Corriente
A20: Valor actual: [VALOR]
A21: Interpretación: [TEXTO CONDICIONAL BASADO EN VALOR]
A23: 2.2 Prueba Ácida
A24: Valor actual: [VALOR]
A25: Interpretación: [TEXTO CONDICIONAL]
... A138: profesional contable para validar interpretaciones y recomendaciones.

Sheet INFORME VISUAL
A1: DASHBOARD EJECUTIVO
A3: Gráfico 1: Evolución de Ventas y Utilidades
A4: [Espacio reservado para gráfico - se generará con macro VBA]
K5: Año | L5: Ventas | M5: Utilidad Neta
K6: 2022 | L6: =EERR!B5 | M6: =EERR!B22
K7: 2023 | L7: =EERR!D5 | M7: =EERR!D22
K8: 2024 | L8: =EERR!G5 | M8: =EERR!G22
K11: Margen | L11: 2022 | M11: 2023 | N11: 2024
K12: Bruto | L12: =INDICADORES!C16 | M12: =INDICADORES!D16 | N12: =INDICADORES!G16
K13: EBITDA | L13: =INDICADORES!C17 | M13: =INDICADORES!D17 | N13: =INDICADORES!G17
K14: Operativo | L14: =INDICADORES!C18 | M14: =INDICADORES!D18 | N14: =INDICADORES!G18
K15: Neto | L15: =INDICADORES!C19 | M15: =INDICADORES!D19 | N15: =INDICADORES!G19
A18: Gráfico 2: Comparación de Márgenes (Bruto, EBITDA, Operativo, Neto) | K18: Componente | L18: Valor
A19: [Espacio reservado para gráfico - se generará con macro VBA] | K19: Activos Corrientes | L19: =ESF!G14
K20: Activos No Corrientes | L20: =ESF!G21
K23: Componente | L23: Valor
K24: Pasivos | L24: =ESF!G45
K25: Patrimonio | L25: =ESF!G54
K28: Concepto | L28: Días
K29: Días Inventario | L29: =INDICADORES!G33
K30: Días Cartera | L30: =INDICADORES!G35
K31: Días Proveedores | L31: =INDICADORES!G37
K32: Ciclo Efectivo | L32: =INDICADORES!G39
A33: Gráfico 3: Composición del Activo
A34: [Espacio reservado para gráfico - se generará con macro VBA]
A48: Gráfico 4: Composición del Pasivo y Patrimonio
A49: [Espacio reservado para gráfico - se generará con macro VBA]
A63: Gráfico 5: Punto de Equilibrio
A64: [Espacio reservado para gráfico - se generará con macro VBA]
A78: Gráfico 6: Comparación con Industria (Radar)
A79: [Espacio reservado para gráfico - se generará con macro VBA]
A93: Gráfico 7: Ciclo de Conversión de Efectivo
A94: [Espacio reservado para gráfico - se generará con macro VBA]
A108: Gráfico 8: Indicadores de Liquidez y Endeudamiento
A109: [Espacio reservado para gráfico - se generará con macro VBA]
